Workbook

Sheet Summary
A1: NIKTIMVO™ (Axatilimab-csfr) Field Force Sizing | cGVHD | United States
A2: Drug / Brand: | B2: Niktimvo™ (axatilimab-csfr)
A3: Indication: | B3: Chronic GVHD (cGVHD) — ≥2 prior lines of systemic therapy
A4: Geography: | B4: United States
A5: Market Type: | B5: RARE DISEASE (US Orphan Drug Act threshold; ~17,000 cGVHD patients US; narrow allo-HSCT center-of-excellence model)
A6: Market Confidence: | B6: High — FDA orphan drug approval Aug 2024; first-in-class anti-CSF-1R
A7: Date: | B7: June 2026
A8: Total Target HCPs: | B8: 12,140
A10: COMPETITOR SALESFORCE-SIZING BENCHMARK
A11: Competitor benchmarks (cGVHD 3rd-line specialty setting): Belumosudil (Rezurock/Kadmon–Sanofi) launched 2021 with a focused specialty sales team (~20–40 GVHD-specialist reps at launch per public earnings commentary and allo-HSCT center footprint); Ruxolitinib (Jakafi/Incyte) — large hematology oncology field >500 reps but multi-indication, not GVHD-specific. No reliable public salesforce-size number was found for Niktimvo (Incyte+Syndax co-commercialized). Assessment: cGVHD is a narrow rare-disease market served by allo-HSCT centers of excellence; competitive benchmarks support a SMALL, HIGHLY FOCUSED specialist field force in the 20–60 rep range. This benchmark supports lower-intensity rare-disease reach/call defaults and validates Conservative–Moderate sizing.
A13: REP COUNT DASHBOARD — All 10 Scenario Outputs
A14: Scenario Family | B14: Sub-Scenario | C14: Reps Required | D14: vs. Normal Workload | H14: Notes
A15: Normal Workload (Baseline) | B15: Normal Workload | C15: =Normal_Workload!H16 -> 39 | D15: =C15-C15 -> 0 | H15: BASELINE — Moderate reach, Standard frequency, Balanced segment
A16: Reach | B16: Aggressive | C16: =Reach_Scenario!H9 -> 45 | D16: =C16-C15 -> 6 | H16: Max reach; capped at rare-disease starting anchor (90% T1)
A17: Reach | B17: Moderate ★ Baseline | C17: =Reach_Scenario!H20 -> 39 | D17: =C17-C15 -> 0 | H17: Equal to Normal Workload reach
A18: Reach | B18: Conservative | C18: =Reach_Scenario!H31 -> 29 | D18: =C18-C15 -> -10 | H18: Lower reach; cost-sensitive scenario
A19: Frequency | B19: High-touch | C19: =Frequency_Scenario!H9 -> 58 | D19: =C19-C15 -> 19 | H19: One step above Standard calls/HCP/yr
A20: Frequency | B20: Standard ★ Baseline | C20: =Frequency_Scenario!H20 -> 39 | D20: =C20-C15 -> 0 | H20: Equal to Normal Workload calls/HCP/yr
A21: Frequency | B21: Low-touch | C21: =Frequency_Scenario!H31 -> 33 | D21: =C21-C15 -> -6 | H21: One step below Standard; minimum 6 calls/yr
A22: Segment | B22: Premium-tilt | C22: =Segment_Scenario!H14 -> 31 | D22: =C22-C15 -> -8 | H22: Higher share of High-intensity HCPs
A23: Segment | B23: Balanced ★ Baseline | C23: =Segment_Scenario!H27 -> 29 | D23: =C23-C15 -> -10 | H23: Reference segment mix
A24: Segment | B24: Cost-aware | C24: =Segment_Scenario!H40 -> 27 | D24: =C24-C15 -> -12 | H24: More Low-intensity HCPs in each tier
A26: CHART: Reps Required Across All 10 Scenarios (embedded bar chart below — auto-updates with inputs)
A28: RECOMMENDATION
A29: Recommended sizing: NORMAL WORKLOAD baseline (Moderate reach / Standard frequency / Balanced segment). For a new launch (Aug 2024) in a rare-disease, center-of-excellence market (~17,000 cGVHD patients, ~14,000 needing systemic therapy, ~8,000 eligible ≥2L), the sizing model yields a focused specialist field force. Recommended rep count = Normal Workload output (see cell C15). Strategic range for leadership review: Conservative to Moderate reach scenario. Competitive benchmarks (Rezurock launch ~20–40 reps; allo-HSCT specialty footprint) confirm a lean, high-touch specialist model is appropriate. Do NOT default to broad oncology field force benchmarks — the accessible patient population is far more concentrated. Sources: FDA label (Aug 2024); Pharmacy Times (Feb 2025); FiercePharma Rezurock launch coverage (Jul 2021); cGVHD prevalence: ~17,000 US (Pharmacy Times 2025); AGAVE-201 (NEJM/AACRJNCI 2025).
A31: KEY ASSUMPTION RATIONALE
A32: • Market Type: RARE — cGVHD affects ~17,000 US patients; ~14,000 need systemic therapy; ≥2L eligible ~8,400. FDA Orphan Drug Act threshold (<200k). Rare-disease defaults applied.
A33: • Reach: Rare-market anchors — T1 (Seg A) 90%, T2 (Seg B) 75%, T3 (Seg C) 60%, T4 (Seg D) 45%. Rare top-tier starting anchor (90%) per skill rules.
A34: • Calls/HCP/yr: Rare-market standard — T1=18, T2=12, T3=6, T4=6 (all multiples of 6). New launch adjustment: T1/T2 bumped one step vs. mature therapy baseline.
A35: • Capacity: 220 working days/year, 6 calls/day = 1,320 calls/rep/year (standard rare/specialty field force).
A36: • Segment: Tiers use HCPTIER field (Segment A–D). No ENG-2 field detected in dataset; not modeled.
A37: • No 100% reach seeded; all reach values capped at max reach cap (90% for rare). CEILING used for all rep counts.
A47: Scenario Label | B47: Reps Required
A48: Normal Workload | B48: =Normal_Workload!H16 -> 39
A49: Reach — Aggressive | B49: =Reach_Scenario!H9 -> 45
A50: Reach — Moderate | B50: =Reach_Scenario!H20 -> 39
A51: Reach — Conservative | B51: =Reach_Scenario!H31 -> 29
A52: Freq — High-touch | B52: =Frequency_Scenario!H9 -> 58
A53: Freq — Standard | B53: =Frequency_Scenario!H20 -> 39
A54: Freq — Low-touch | B54: =Frequency_Scenario!H31 -> 33
...

Sheet Inputs
A1: INPUTS — Generic Workbook Levers (Edit Yellow Cells)
A3: CAPACITY PARAMETERS
A4: Working Days / Year | B4: 220 | D4: Productive field days per rep per year
A5: Calls / Day | B5: 6 | D5: Base rep daily call productivity
A6: Rep Annual Capacity | B6: =B4*B5 -> 1320 | D6: Working Days × Calls/Day
A8: MARKET INTELLIGENCE
A9: Drug | B9: Niktimvo™ (axatilimab-csfr) | D9: Brand name of drug being sized
A10: Indication | B10: Chronic GVHD (cGVHD) — ≥2 prior lines of systemic therapy | D10: FDA-approved indication
A11: Geography | B11: United States | D11: Commercial reference market
A12: Market Type Classification | B12: RARE | D12: US Orphan Drug Act: <200,000 patients; cGVHD ~17,000 US
A13: Market Confidence | B13: High | D13: FDA approved Aug 2024; clear rare-disease epidemiology
A14: Competitor Benchmark Range | B14: ~20–40 specialist reps (inferred from Rezurock/Kadmon launch footprint) | D14: See Diagnostics_QA for full evidence
A15: Max Reach Cap (%) | B15: 0.9 | D15: Rare-disease top-tier cap. Editable. Never set above 0.90 for rare.
A17: HCP COUNTS BY TIER (from dataset)
A18: Segment A (Tier 1) — HCP Count | B18: 519 | D18: Source: Sizing_Input.xlsx
A19: Segment B (Tier 2) — HCP Count | B19: 1137 | D19: Source: Sizing_Input.xlsx
A20: Segment C (Tier 3) — HCP Count | B20: 4657 | D20: Source: Sizing_Input.xlsx
A21: Segment D (Tier 4) — HCP Count | B21: 5827 | D21: Source: Sizing_Input.xlsx
A22: Total HCPs | B22: =B18+B19+B20+B21 -> 12140 | D22: Sum of all tiers
A24: BASE CALLS/HCP/YEAR (Rare Disease — New Launch Anchors)
A25: Segment A (Tier 1) — Calls/HCP/Yr | B25: 18 | D25: Rare T1 baseline. Multiple of 6. Editable.
A26: Segment B (Tier 2) — Calls/HCP/Yr | B26: 12 | D26: Rare T2 baseline. Multiple of 6. Editable.
A27: Segment C (Tier 3) — Calls/HCP/Yr | B27: 6 | D27: Rare T3 baseline. Multiple of 6. Editable.
A28: Segment D (Tier 4) — Calls/HCP/Yr | B28: 6 | D28: Rare T4 baseline. Multiple of 6. Editable.

Sheet Normal_Workload
A1: NORMAL WORKLOAD — Baseline Scenario (Moderate Reach / Standard Frequency / Balanced Segment)
A2: Rep Annual Capacity = Working Days × Calls/Day | E2: =Inputs!B6 -> 1320 | F2: calls/rep/year
A3: Baseline reach (Moderate / Rare-market anchors): | B3: T1 = 90% | T2 = 75% | T3 = 60% | T4 = 45% [editable below in yellow — capped at Inputs!B15]
A5: Tier | B5: HCP Count | C5: Reach % | D5: Effective HCPs | E5: Calls/HCP/Year | F5: Total Calls | G5: Reps Required
A6: Segment A | B6: =Inputs!B18 -> 519 | C6: 0.9 | D6: =ROUND(B6*C6,0) -> 467 | E6: =Inputs!B25 -> 18 | F6: =D6*E6 -> 8406
A7: Segment B | B7: =Inputs!B19 -> 1137 | C7: 0.75 | D7: =ROUND(B7*C7,0) -> 853 | E7: =Inputs!B26 -> 12 | F7: =D7*E7 -> 10236
A8: Segment C | B8: =Inputs!B20 -> 4657 | C8: 0.6 | D8: =ROUND(B8*C8,0) -> 2794 | E8: =Inputs!B27 -> 6 | F8: =D8*E8 -> 16764
A9: Segment D | B9: =Inputs!B21 -> 5827 | C9: 0.45 | D9: =ROUND(B9*C9,0) -> 2622 | E9: =Inputs!B28 -> 6 | F9: =D9*E9 -> 15732
A10: TOTAL / REPS REQUIRED | D10: =SUM(D6:D9) -> 6736 | E10: — | F10: =SUM(F6:F9) -> 51138 | G10: =CEILING(F10/Inputs!B6,1) -> 39
A12: Normal Workload = Moderate reach (rare anchors: T1 90%, T2 75%, T3 60%, T4 45%) × Standard frequency (T1 18, T2 12, T3 6, T4 6 calls/HCP/yr) × Balanced segment mix. Edit yellow cells to override defaults. All reach values must remain ≤ Inputs!B15 (90% rare cap).
H16: =G10 -> 39

Sheet Reach_Scenario
A1: REACH SCENARIO — Only Reach % changes. Calls/HCP/yr fixed from Normal_Workload.
A3: Aggressive Reach (Top-tier at rare cap; lower tiers tapered)
A4: Tier | B4: HCP Count | C4: Reach % | D4: Effective HCPs | E4: Calls/HCP/Year | F4: Total Calls | G4: Reps Required
A5: Segment A | B5: =Inputs!B18 -> 519 | C5: 0.9 | D5: =ROUND(B5*C5,0) -> 467 | E5: =Normal_Workload!E6 -> 18 | F5: =D5*E5 -> 8406
A6: Segment B | B6: =Inputs!B19 -> 1137 | C6: 0.85 | D6: =ROUND(B6*C6,0) -> 966 | E6: =Normal_Workload!E7 -> 12 | F6: =D6*E6 -> 11592
A7: Segment C | B7: =Inputs!B20 -> 4657 | C7: 0.7 | D7: =ROUND(B7*C7,0) -> 3260 | E7: =Normal_Workload!E8 -> 6 | F7: =D7*E7 -> 19560
A8: Segment D | B8: =Inputs!B21 -> 5827 | C8: 0.55 | D8: =ROUND(B8*C8,0) -> 3205 | E8: =Normal_Workload!E9 -> 6 | F8: =D8*E8 -> 19230
A9: TOTAL / REPS REQUIRED | D9: =SUM(D5:D8) -> 7898 | E9: — | F9: =SUM(F5:F8) -> 58788 | G9: =CEILING(F9/Inputs!B6,1) -> 45 | H9: =G9 -> 45
A14: Moderate Reach ★ BASELINE (Equal to Normal_Workload — Rare anchors)
A15: Tier | B15: HCP Count | C15: Reach % | D15: Effective HCPs | E15: Calls/HCP/Year | F15: Total Calls | G15: Reps Required
A16: Segment A | B16: =Inputs!B18 -> 519 | C16: =Normal_Workload!C6 -> 0.9 | D16: =ROUND(B16*C16,0) -> 467 | E16: =Normal_Workload!E6 -> 18 | F16: =D16*E16 -> 8406
A17: Segment B | B17: =Inputs!B19 -> 1137 | C17: =Normal_Workload!C7 -> 0.75 | D17: =ROUND(B17*C17,0) -> 853 | E17: =Normal_Workload!E7 -> 12 | F17: =D17*E17 -> 10236
A18: Segment C | B18: =Inputs!B20 -> 4657 | C18: =Normal_Workload!C8 -> 0.6 | D18: =ROUND(B18*C18,0) -> 2794 | E18: =Normal_Workload!E8 -> 6 | F18: =D18*E18 -> 16764
A19: Segment D | B19: =Inputs!B21 -> 5827 | C19: =Normal_Workload!C9 -> 0.45 | D19: =ROUND(B19*C19,0) -> 2622 | E19: =Normal_Workload!E9 -> 6 | F19: =D19*E19 -> 15732
A20: TOTAL / REPS REQUIRED | D20: =SUM(D16:D19) -> 6736 | E20: — | F20: =SUM(F16:F19) -> 51138 | G20: =CEILING(F20/Inputs!B6,1) -> 39 | H20: =G20 -> 39
A25: Conservative Reach (Lower coverage; cost-sensitive or access-constrained)
A26: Tier | B26: HCP Count | C26: Reach % | D26: Effective HCPs | E26: Calls/HCP/Year | F26: Total Calls | G26: Reps Required
A27: Segment A | B27: =Inputs!B18 -> 519 | C27: 0.75 | D27: =ROUND(B27*C27,0) -> 389 | E27: =Normal_Workload!E6 -> 18 | F27: =D27*E27 -> 7002
A28: Segment B | B28: =Inputs!B19 -> 1137 | C28: 0.6 | D28: =ROUND(B28*C28,0) -> 682 | E28: =Normal_Workload!E7 -> 12 | F28: =D28*E28 -> 8184
A29: Segment C | B29: =Inputs!B20 -> 4657 | C29: 0.45 | D29: =ROUND(B29*C29,0) -> 2096 | E29: =Normal_Workload!E8 -> 6 | F29: =D29*E29 -> 12576
A30: Segment D | B30: =Inputs!B21 -> 5827 | C30: 0.3 | D30: =ROUND(B30*C30,0) -> 1748 | E30: =Normal_Workload!E9 -> 6 | F30: =D30*E30 -> 10488
A31: TOTAL / REPS REQUIRED | D31: =SUM(D27:D30) -> 4915 | E31: — | F31: =SUM(F27:F30) -> 38250 | G31: =CEILING(F31/Inputs!B6,1) -> 29 | H31: =G31 -> 29
A36: PARITY: Calls/HCP/yr on every tier is formula-linked from Normal_Workload. Only reach % changes across sub-scenarios. Max reach cap = Inputs!B15 (90% for rare market). Moderate reach = Normal_Workload by formula.

Sheet Frequency_Scenario
A1: FREQUENCY SCENARIO — Only Calls/HCP/yr changes. Reach % fixed from Normal_Workload.
A3: High-touch Frequency (One step above Standard; T1=24, T2=18, T3=12, T4=6)
A4: Tier | B4: HCP Count | C4: Reach % | D4: Effective HCPs | E4: Calls/HCP/Year | F4: Total Calls | G4: Reps Required
A5: Segment A | B5: =Inputs!B18 -> 519 | C5: =Normal_Workload!C6 -> 0.9 | D5: =ROUND(B5*C5,0) -> 467 | E5: 24 | F5: =D5*E5 -> 11208
A6: Segment B | B6: =Inputs!B19 -> 1137 | C6: =Normal_Workload!C7 -> 0.75 | D6: =ROUND(B6*C6,0) -> 853 | E6: 18 | F6: =D6*E6 -> 15354
A7: Segment C | B7: =Inputs!B20 -> 4657 | C7: =Normal_Workload!C8 -> 0.6 | D7: =ROUND(B7*C7,0) -> 2794 | E7: 12 | F7: =D7*E7 -> 33528
A8: Segment D | B8: =Inputs!B21 -> 5827 | C8: =Normal_Workload!C9 -> 0.45 | D8: =ROUND(B8*C8,0) -> 2622 | E8: 6 | F8: =D8*E8 -> 15732
A9: TOTAL / REPS REQUIRED | D9: =SUM(D5:D8) -> 6736 | E9: — | F9: =SUM(F5:F8) -> 75822 | G9: =CEILING(F9/Inputs!B6,1) -> 58 | H9: =G9 -> 58
A14: Standard Frequency ★ BASELINE (Equal to Normal_Workload calls/HCP/yr)
A15: Tier | B15: HCP Count | C15: Reach % | D15: Effective HCPs | E15: Calls/HCP/Year | F15: Total Calls | G15: Reps Required
A16: Segment A | B16: =Inputs!B18 -> 519 | C16: =Normal_Workload!C6 -> 0.9 | D16: =ROUND(B16*C16,0) -> 467 | E16: =Normal_Workload!E6 -> 18 | F16: =D16*E16 -> 8406
A17: Segment B | B17: =Inputs!B19 -> 1137 | C17: =Normal_Workload!C7 -> 0.75 | D17: =ROUND(B17*C17,0) -> 853 | E17: =Normal_Workload!E7 -> 12 | F17: =D17*E17 -> 10236
A18: Segment C | B18: =Inputs!B20 -> 4657 | C18: =Normal_Workload!C8 -> 0.6 | D18: =ROUND(B18*C18,0) -> 2794 | E18: =Normal_Workload!E8 -> 6 | F18: =D18*E18 -> 16764
A19: Segment D | B19: =Inputs!B21 -> 5827 | C19: =Normal_Workload!C9 -> 0.45 | D19: =ROUND(B19*C19,0) -> 2622 | E19: =Normal_Workload!E9 -> 6 | F19: =D19*E19 -> 15732
A20: TOTAL / REPS REQUIRED | D20: =SUM(D16:D19) -> 6736 | E20: — | F20: =SUM(F16:F19) -> 51138 | G20: =CEILING(F20/Inputs!B6,1) -> 39 | H20: =G20 -> 39
A25: Low-touch Frequency (One step below Standard; minimum 6; T1=12, T2=6, T3=6, T4=6)
A26: Tier | B26: HCP Count | C26: Reach % | D26: Effective HCPs | E26: Calls/HCP/Year | F26: Total Calls | G26: Reps Required
A27: Segment A | B27: =Inputs!B18 -> 519 | C27: =Normal_Workload!C6 -> 0.9 | D27: =ROUND(B27*C27,0) -> 467 | E27: 12 | F27: =D27*E27 -> 5604
A28: Segment B | B28: =Inputs!B19 -> 1137 | C28: =Normal_Workload!C7 -> 0.75 | D28: =ROUND(B28*C28,0) -> 853 | E28: 6 | F28: =D28*E28 -> 5118
A29: Segment C | B29: =Inputs!B20 -> 4657 | C29: =Normal_Workload!C8 -> 0.6 | D29: =ROUND(B29*C29,0) -> 2794 | E29: 6 | F29: =D29*E29 -> 16764
A30: Segment D | B30: =Inputs!B21 -> 5827 | C30: =Normal_Workload!C9 -> 0.45 | D30: =ROUND(B30*C30,0) -> 2622 | E30: 6 | F30: =D30*E30 -> 15732
A31: TOTAL / REPS REQUIRED | D31: =SUM(D27:D30) -> 6736 | E31: — | F31: =SUM(F27:F30) -> 43218 | G31: =CEILING(F31/Inputs!B6,1) -> 33 | H31: =G31 -> 33
A36: PARITY: Reach % on every tier is formula-linked from Normal_Workload. Only calls/HCP/yr changes. All calls/HCP/yr values are multiples of 6; minimum = 6. Standard calls/HCP/yr = Normal_Workload. If Standard is already 6, Low-touch may equal 6.

Sheet Segment_Scenario
A1: SEGMENT SCENARIO — Only High/Low segment split changes. Reach and Calls fixed from Normal_Workload.
A3: Premium-tilt (Higher share of High-intensity HCPs in each tier)
A4: Tier | B4: Segment | C4: HCP Count | D4: Split % | E4: Segment HCPs | F4: Reach % | G4: Effective HCPs | H4: Calls/HCP/yr | I4: Total Calls | J4: Reps Required
A5: Segment A | B5: High | C5: =Inputs!B18 -> 519 | D5: 0.7 | E5: =ROUND(C5*D5,0) -> 363 | F5: =Normal_Workload!C6 -> 0.9 | G5: =ROUND(E5*F5,0) -> 327 | H5: =Normal_Workload!E6 -> 18 | I5: =G5*H5 -> 5886
B6: Low | C6: =Inputs!B18 -> 519 | D6: 0.3 | E6: =ROUND(C6*D6,0) -> 156 | F6: =MAX(Normal_Workload!C6-0.15, 0) -> 0.75 | G6: =ROUND(E6*F6,0) -> 117 | H6: =MAX(Normal_Workload!E6-6,6) -> 12 | I6: =G6*H6 -> 1404
A7: Segment B | B7: High | C7: =Inputs!B19 -> 1137 | D7: 0.5 | E7: =ROUND(C7*D7,0) -> 569 | F7: =Normal_Workload!C7 -> 0.75 | G7: =ROUND(E7*F7,0) -> 427 | H7: =Normal_Workload!E7 -> 12 | I7: =G7*H7 -> 5124
B8: Low | C8: =Inputs!B19 -> 1137 | D8: 0.5 | E8: =ROUND(C8*D8,0) -> 569 | F8: =MAX(Normal_Workload!C7-0.15, 0) -> 0.6 | G8: =ROUND(E8*F8,0) -> 341 | H8: =MAX(Normal_Workload!E7-6,6) -> 6 | I8: =G8*H8 -> 2046
A9: Segment C | B9: High | C9: =Inputs!B20 -> 4657 | D9: 0.3 | E9: =ROUND(C9*D9,0) -> 1397 | F9: =Normal_Workload!C8 -> 0.6 | G9: =ROUND(E9*F9,0) -> 838 | H9: =Normal_Workload!E8 -> 6 | I9: =G9*H9 -> 5028
B10: Low | C10: =Inputs!B20 -> 4657 | D10: 0.7 | E10: =ROUND(C10*D10,0) -> 3260 | F10: =MAX(Normal_Workload!C8-0.15, 0) -> 0.45 | G10: =ROUND(E10*F10,0) -> 1467 | H10: =MAX(Normal_Workload!E8-6,6) -> 6 | I10: =G10*H10 -> 8802
A11: Segment D | B11: High | C11: =Inputs!B21 -> 5827 | D11: 0.2 | E11: =ROUND(C11*D11,0) -> 1165 | F11: =Normal_Workload!C9 -> 0.45 | G11: =ROUND(E11*F11,0) -> 524 | H11: =Normal_Workload!E9 -> 6 | I11: =G11*H11 -> 3144
B12: Low | C12: =Inputs!B21 -> 5827 | D12: 0.8 | E12: =ROUND(C12*D12,0) -> 4662 | F12: =MAX(Normal_Workload!C9-0.15, 0) -> 0.3 | G12: =ROUND(E12*F12,0) -> 1399 | H12: =MAX(Normal_Workload!E9-6,6) -> 6 | I12: =G12*H12 -> 8394
A13: TOTAL / REPS REQUIRED | F13: — | G13: =SUM(G5:G12) -> 5440 | H13: — | I13: =SUM(I5:I12) -> 39828 | J13: =CEILING(I13/Inputs!B6,1) -> 31
H14: =J13 -> 31
A16: Balanced ★ BASELINE (Reference segment mix)
A17: Tier | B17: Segment | C17: HCP Count | D17: Split % | E17: Segment HCPs | F17: Reach % | G17: Effective HCPs | H17: Calls/HCP/yr | I17: Total Calls | J17: Reps Required
A18: Segment A | B18: High | C18: =Inputs!B18 -> 519 | D18: 0.5 | E18: =ROUND(C18*D18,0) -> 260 | F18: =Normal_Workload!C6 -> 0.9 | G18: =ROUND(E18*F18,0) -> 234 | H18: =Normal_Workload!E6 -> 18 | I18: =G18*H18 -> 4212
B19: Low | C19: =Inputs!B18 -> 519 | D19: 0.5 | E19: =ROUND(C19*D19,0) -> 260 | F19: =MAX(Normal_Workload!C6-0.15, 0) -> 0.75 | G19: =ROUND(E19*F19,0) -> 195 | H19: =MAX(Normal_Workload!E6-6,6) -> 12 | I19: =G19*H19 -> 2340
A20: Segment B | B20: High | C20: =Inputs!B19 -> 1137 | D20: 0.35 | E20: =ROUND(C20*D20,0) -> 398 | F20: =Normal_Workload!C7 -> 0.75 | G20: =ROUND(E20*F20,0) -> 299 | H20: =Normal_Workload!E7 -> 12 | I20: =G20*H20 -> 3588
B21: Low | C21: =Inputs!B19 -> 1137 | D21: 0.65 | E21: =ROUND(C21*D21,0) -> 739 | F21: =MAX(Normal_Workload!C7-0.15, 0) -> 0.6 | G21: =ROUND(E21*F21,0) -> 443 | H21: =MAX(Normal_Workload!E7-6,6) -> 6 | I21: =G21*H21 -> 2658
A22: Segment C | B22: High | C22: =Inputs!B20 -> 4657 | D22: 0.25 | E22: =ROUND(C22*D22,0) -> 1164 | F22: =Normal_Workload!C8 -> 0.6 | G22: =ROUND(E22*F22,0) -> 698 | H22: =Normal_Workload!E8 -> 6 | I22: =G22*H22 -> 4188
B23: Low | C23: =Inputs!B20 -> 4657 | D23: 0.75 | E23: =ROUND(C23*D23,0) -> 3493 | F23: =MAX(Normal_Workload!C8-0.15, 0) -> 0.45 | G23: =ROUND(E23*F23,0) -> 1572 | H23: =MAX(Normal_Workload!E8-6,6) -> 6 | I23: =G23*H23 -> 9432
A24: Segment D | B24: High | C24: =Inputs!B21 -> 5827 | D24: 0.15 | E24: =ROUND(C24*D24,0) -> 874 | F24: =Normal_Workload!C9 -> 0.45 | G24: =ROUND(E24*F24,0) -> 393 | H24: =Normal_Workload!E9 -> 6 | I24: =G24*H24 -> 2358
B25: Low | C25: =Inputs!B21 -> 5827 | D25: 0.85 | E25: =ROUND(C25*D25,0) -> 4953 | F25: =MAX(Normal_Workload!C9-0.15, 0) -> 0.3 | G25: =ROUND(E25*F25,0) -> 1486 | H25: =MAX(Normal_Workload!E9-6,6) -> 6 | I25: =G25*H25 -> 8916
A26: TOTAL / REPS REQUIRED | F26: — | G26: =SUM(G18:G25) -> 5320 | H26: — | I26: =SUM(I18:I25) -> 37692 | J26: =CEILING(I26/Inputs!B6,1) -> 29
H27: =J26 -> 29
A29: Cost-aware (More Low-intensity HCPs; conservative resource deployment)
A30: Tier | B30: Segment | C30: HCP Count | D30: Split % | E30: Segment HCPs | F30: Reach % | G30: Effective HCPs | H30: Calls/HCP/yr | I30: Total Calls | J30: Reps Required
A31: Segment A | B31: High | C31: =Inputs!B18 -> 519 | D31: 0.3 | E31: =ROUND(C31*D31,0) -> 156 | F31: =Normal_Workload!C6 -> 0.9 | G31: =ROUND(E31*F31,0) -> 140 | H31: =Normal_Workload!E6 -> 18 | I31: =G31*H31 -> 2520
B32: Low | C32: =Inputs!B18 -> 519 | D32: 0.7 | E32: =ROUND(C32*D32,0) -> 363 | F32: =MAX(Normal_Workload!C6-0.15, 0) -> 0.75 | G32: =ROUND(E32*F32,0) -> 272 | H32: =MAX(Normal_Workload!E6-6,6) -> 12 | I32: =G32*H32 -> 3264
A33: Segment B | B33: High | C33: =Inputs!B19 -> 1137 | D33: 0.2 | E33: =ROUND(C33*D33,0) -> 227 | F33: =Normal_Workload!C7 -> 0.75 | G33: =ROUND(E33*F33,0) -> 170 | H33: =Normal_Workload!E7 -> 12 | I33: =G33*H33 -> 2040
B34: Low | C34: =Inputs!B19 -> 1137 | D34: 0.8 | E34: =ROUND(C34*D34,0) -> 910 | F34: =MAX(Normal_Workload!C7-0.15, 0) -> 0.6 | G34: =ROUND(E34*F34,0) -> 546 | H34: =MAX(Normal_Workload!E7-6,6) -> 6 | I34: =G34*H34 -> 3276
A35: Segment C | B35: High | C35: =Inputs!B20 -> 4657 | D35: 0.15 | E35: =ROUND(C35*D35,0) -> 699 | F35: =Normal_Workload!C8 -> 0.6 | G35: =ROUND(E35*F35,0) -> 419 | H35: =Normal_Workload!E8 -> 6 | I35: =G35*H35 -> 2514
B36: Low | C36: =Inputs!B20 -> 4657 | D36: 0.85 | E36: =ROUND(C36*D36,0) -> 3958 | F36: =MAX(Normal_Workload!C8-0.15, 0) -> 0.45 | G36: =ROUND(E36*F36,0) -> 1781 | H36: =MAX(Normal_Workload!E8-6,6) -> 6 | I36: =G36*H36 -> 10686
A37: Segment D | B37: High | C37: =Inputs!B21 -> 5827 | D37: 0.1 | E37: =ROUND(C37*D37,0) -> 583 | F37: =Normal_Workload!C9 -> 0.45 | G37: =ROUND(E37*F37,0) -> 262 | H37: =Normal_Workload!E9 -> 6 | I37: =G37*H37 -> 1572
B38: Low | C38: =Inputs!B21 -> 5827 | D38: 0.9 | E38: =ROUND(C38*D38,0) -> 5244 | F38: =MAX(Normal_Workload!C9-0.15, 0) -> 0.3 | G38: =ROUND(E38*F38,0) -> 1573 | H38: =MAX(Normal_Workload!E9-6,6) -> 6 | I38: =G38*H38 -> 9438
A39: TOTAL / REPS REQUIRED | F39: — | G39: =SUM(G31:G38) -> 5163 | H39: — | I39: =SUM(I31:I38) -> 35310 | J39: =CEILING(I39/Inputs!B6,1) -> 27
H40: =J39 -> 27

Sheet Diagnostics_QA
A1: DIAGNOSTICS & QA — Background tab. Not for leadership distribution.
A3: 1. MARKET CLASSIFICATION EVIDENCE
A4: Drug | B4: Niktimvo™ (axatilimab-csfr)
A5: Indication | B5: Chronic graft-versus-host disease (cGVHD) after ≥2 prior lines of systemic therapy
A6: Geography | B6: United States
A7: Classification | B7: RARE — US Orphan Drug Act threshold: <200,000 patients. cGVHD affects ~17,000 US individuals. FDA granted Orphan Drug Designation. First US approval August 14, 2024.
A8: Source 1 | B8: Pharmacy Times, Feb 2025: 'cGVHD occurs after an allogeneic stem cell transplant in around 42% of transplant recipients and impacts approximately 17,000 US individuals.' URL: pharmacytimes.com/view/fda-approves-axatilimab-csfr-9-mg-and-22-mg-vial-sizes-for-cgvhd. Accessed: June 2026.
A9: Source 2 | B9: FDA approval summary: AACRJNCI CCR, Sep 2025. axatilimab approved Aug 14, 2024 for cGVHD ≥2L. URL: aacrjournals.org/clincancerres/article/31/17/3607. Accessed: June 2026.
A10: Source 3 | B10: FDA label (NIKTIMVO), Aug 2024: orphan indication, IV infusion every 2 weeks. URL: accessdata.fda.gov/drugsatfda_docs/label/2024/761411s000lbl.pdf. Accessed: June 2026.
A11: Confidence | B11: HIGH — clear orphan-drug classification, well-characterized prevalence, FDA-approved label confirms indication scope.
A13: 2. COMPETITOR SALESFORCE-SIZING EVIDENCE
A14: Competitor 1 | B14: Belumosudil (Rezurock) — Kadmon/Sanofi. Same indication: cGVHD ≥2L. Approved July 2021.
A15: Rezurock SF Size | B15: Inferred ~20–40 specialty reps at launch. FiercePharma (Jul 2021): Kadmon CCO Taitel referenced a 'primed sales team' focused on allo-HSCT centers and transplant hematology specialists; estimated 14,000 patients/yr needing systemic therapy. No exact number published. Source: fiercepharma.com/pharma/kadmon-eyes-15-5k-pricetag. Accessed: June 2026.
A16: Rezurock Influence | B16: This benchmark supports a LEAN specialist field force. A broad general oncology deployment would be over-resourced for the concentrated cGVHD care pathway (allo-HSCT centers, transplant hematologists).
A17: Competitor 2 | B17: Ruxolitinib (Jakafi) — Incyte. Approved for cGVHD but large multi-indication product (MF, PV, aGVHD, cGVHD). Hematology oncology field >500+ reps; NOT a reliable benchmark for cGVHD-specific sizing.
A18: Niktimvo SF | B18: No reliable public salesforce-size number found for Niktimvo (Incyte+Syndax co-commercialized launch, Feb 2025). Incyte CEO referenced 'deep understanding of cGVHD community' but no rep count. Source: Incyte press release Jan 2025. URL: investor.incyte.com. Accessed: June 2026.
A19: Benchmark Range | B19: ~20–60 specialist reps (inferred from Rezurock launch, allo-HSCT center footprint, rare-disease market dynamics).
A20: Influence on Model | B20: Competitor benchmarks validate rare-disease T1 reach starting anchor (90%), standard frequency (18/12/6/6 calls/yr), and a total rep count well below general-oncology field force benchmarks.
A22: 3. DEFAULTING RATIONALE
A23: Market Type | B23: RARE — drove all defaults
A24: T1 Reach (Moderate) | B24: 90% — Rare market top-tier starting anchor per skill rules. Not 95% (non-rare cap).
A25: T2 Reach (Moderate) | B25: 75% — Tapered from T1
A26: T3 Reach (Moderate) | B26: 60%
A27: T4 Reach (Moderate) | B27: 45%
A28: T1 Calls/HCP/yr | B28: 18 — Rare baseline. New launch +1 step vs. mature therapy (12→18). Multiple of 6.
A29: T2 Calls/HCP/yr | B29: 12
A30: T3 Calls/HCP/yr | B30: 6 — Minimum multiple of 6
A31: T4 Calls/HCP/yr | B31: 6 — Same as T3; rare/restricted lower tier at floor
A32: Launch Maturity | B32: NEW LAUNCH (FDA Aug 2024; commercial Feb 2025). Justifies T1/T2 calls at upper rare-market anchor. Does NOT justify non-rare broad-market reach.
A33: Access restrictions | B33: IV infusion every 2 weeks; administered at allo-HSCT centers or specialty infusion centers. Highly concentrated patient population. Supports center-of-excellence model.
A34: Client Overrides | B34: None. All defaults derived from drug + market type + launch maturity evidence. Yellow editable cells allow client to override.
... A37: Multiples of 6 | B37: Confirmed. All calls/HCP/yr values: 6, 12, 18, 24. Validation applied.
A39: 4. DIAGNOSTIC METRICS BY SCENARIO
A40: Scenario | B40: HCP-per-Rep (diagnostic only; not in Summary)
A41: Normal Workload | B41: =IFERROR(Normal_Workload!D10/CEILING(Normal_Workload!F10/Inputs!B6,1),"N/A") -> 172.71795
A42: Reach — Aggressive | B42: =IFERROR(Reach_Scenario!D10/CEILING(Reach_Scenario!F10/Inputs!B6,1),"N/A") -> N/A
A43: Reach — Moderate | B43: =IFERROR(Reach_Scenario!D21/CEILING(Reach_Scenario!F21/Inputs!B6,1),"N/A") -> N/A
A44: Reach — Conservative | B44: =IFERROR(Reach_Scenario!D32/CEILING(Reach_Scenario!F32/Inputs!B6,1),"N/A") -> N/A
A45: Frequency — High-touch | B45: =IFERROR(Frequency_Scenario!D10/CEILING(Frequency_Scenario!F10/Inputs!B6,1),"N/A") -> N/A
A46: Frequency — Standard | B46: =IFERROR(Frequency_Scenario!D21/CEILING(Frequency_Scenario!F21/Inputs!B6,1),"N/A") -> N/A
...
